Workbook

Sheet Cover Page
B2: FINANCIAL ACCOUNTING & ANALYSIS
B4: MAJOR PROJECT REPORT
B6: Industry Study: Paints & Coatings
B8: A Comparative Financial Accounting and Ratio Analysis of Five Listed Indian Paints & Coatings Companies
B9: Berger Paints India Ltd. | Kansai Nerolac Paints Ltd. | Asian Paints Ltd. | Indigo Paints Ltd. | JSW Dulux Ltd. (formerly Akzo Nobel India Ltd.)
B12: Team Members | E12: Company Chosen
B13: Sachi Jain (R012) | E13: Berger Paints India Ltd.
B14: Vidisha Kondinya (R016) | E14: Asian Paints Ltd.
B15: Samruddhi Palodkar (R025) | E15: Indigo Paints Ltd.
B16: Arnav Rathod (R031) | E16: Kansai Nerolac Paints Ltd.
B17: Priyansh Soni (R045) | E17: JSW Dulux Ltd.
B20: MBA Tech (Artificial Intelligence)
B21: SVKM’s NMIMS, Mumbai
B23: Course: Financial Accounting & Analysis (FAA)
B24: Faculty: Dr. Alaknanda Lonare
B25: Academic Year 2026-27 | Submission Date: 15 October 2026

Sheet Berger
A1: Berger Paints India Ltd. - Financial Analysis
A2: Standalone Financial Statements | FY2024–25 & FY2025–26 (FY2023–24 Opening Balances) | Amounts in ₹ Crore Unless Stated | Industry Average: Simple Mean of Five Companies
A4: Financial Statement Analysis
A6: A. Key Financial Figures - Financial Statement Data (₹ Crore) - own company inputs used by the analysis
A7: Line Item | C7: Berger Paints
C8: FY2024-25 | D8: FY2025-26
A9: Inventories (closing stock) | C9: 2206.6 | D9: 2225.6
A10: Trade Receivables (current) | C10: 1124.37 | D10: 1129.27
A11: Cash & Cash Equivalents | C11: 141.39 | D11: 151.94
A12: Bank Balances other than Cash & Cash Equivalents | C12: 224.46 | D12: 55.01
A13: Other Current Assets (investments, loans, other financial & non-financial assets) | C13: 436.98 | D13: 1118.69
A14: Total Current Assets | C14: 4133.8 | D14: 4680.51
A15: Trade Payables | C15: 1569.34 | D15: 1522.26
A16: Short-term Borrowings | C16: 0.39 | D16: 0
A17: Other Current Liabilities & Provisions (incl. current lease liabilities) | C17: 416.03 | D17: 619.85
A18: Total Current Liabilities | C18: 1985.76 | D18: 2142.11
A19: Total Borrowings (interest-bearing debt; excludes lease liabilities) | C19: 0.39 | D19: 0
A20: Total Equity / Shareholders’ Funds | C20: 5681.06 | D20: 6342.9
... A29: Total Lease Liabilities, Ind AS 116 - excluded from Total Borrowings above (memo) | C29: 492.1 | D29: 458.74
A31: Opening Balances - FY2023–24 Closing (Reference Only)
A32: These three FY2023-24 closing figures come from the comparative column already printed in each company’s FY2024-25 annual report (see citations below) and are used only to compute average-balance ratios for FY2024-25 in the tables below - they are not part of the two-year dataset used in the rest of this analysis.
A34: Line Item - As at 31 March 2024 | C34: Berger Paints
A35: Inventories (closing stock) | C35: 2019.43
A36: Total Equity / Shareholders’ Funds | C36: 5005.24
A37: Total Assets | C37: 7581.66
A39: Ratio Analysis - Formula, Company Figures & Industry Average
A40: Methodology: Debt-to-Equity excludes Ind AS 116 lease liabilities; a separate lease-inclusive ratio adds Total Lease Liabilities. The Industry Average is the simple arithmetic mean of the same ratio for the five selected companies, including the company being analysed. Supporting financial data is maintained in the Industry Summary sheet, while company-specific ratios are calculated separately for FY2024–25 and FY2025–26. Ratios based on average balances use FY2023–24 closing balances and FY2024–25 closing balances for FY2024–25, and FY2024–25 and FY2025–26 closing balances for FY2025–26. Materials-Consumption Turnover is used as a proxy for Inventory Turnover because a single consolidated Cost of Goods Sold figure is not available for all companies.
A42: B. Liquidity
C43: FY2024-25 | E43: FY2025-26
A44: Ratio | B44: Formula | C44: Company | D44: Industry Avg | E44: Company | F44: Industry Avg
A45: Current Ratio | B45: Current Assets ÷ Current Liabilities | C45: =C14/C18 -> 2.0817219 | D45: ='Industry Summary'!L48 -> 2.4353778 | E45: =D14/D18 -> 2.1849998 | F45: ='Industry Summary'!L60 -> 2.4275972
A46: Quick Ratio | B46: (Current Assets − Inventories) ÷ Current Liabilities | C46: =(C14-C9)/C18 -> 0.97051003 | D46: ='Industry Summary'!L49 -> 1.5808142 | E46: =(D14-D9)/D18 -> 1.1460242 | F46: ='Industry Summary'!L61 -> 1.6811362
A47: Cash Ratio | B47: (Cash & Cash Equivalents + Other Bank Balances) ÷ Current Liabilities | C47: =(C11+C12)/C18 -> 0.18423677 | D47: ='Industry Summary'!L50 -> 0.15262564 | E47: =(D11+D12)/D18 -> 0.096610351 | F47: ='Industry Summary'!L62 -> 0.11967229
A49: C. Solvency and Leverage
C50: FY2024-25 | E50: FY2025-26
A51: Ratio | B51: Formula | C51: Company | D51: Industry Avg | E51: Company | F51: Industry Avg
A52: Debt-to-Equity | B52: Total Borrowings ÷ Total Equity | C52: =C19/C20 -> 6.8649161e-05 | D52: ='Industry Summary'!L54 -> 0.00042882759 | E52: =D19/D20 -> 0 | F52: ='Industry Summary'!L66 -> 0.011449285
A53: Debt-to-Equity (incl. Lease Liabilities) | B53: (Total Borrowings + Total Lease Liabilities) ÷ Total Equity | C53: =(C19+C29)/C20 -> 0.086689808 | D53: ='Industry Summary'!L55 -> 0.048453003 | E53: =(D19+D29)/D20 -> 0.072323385 | F53: ='Industry Summary'!L67 -> 0.053467726
A55: D. Profitability
C56: FY2024-25 | E56: FY2025-26
...

Sheet Kansai Nerolac
A1: Kansai Nerolac Paints Ltd. - Financial Analysis
A2: Standalone Financial Statements | FY2024–25 & FY2025–26 (FY2023–24 Opening Balances) | Amounts in ₹ Crore Unless Stated | Industry Average: Simple Mean of Five Companies
A4: Financial Statement Analysis
A6: A. Key Financial Figures - Financial Statement Data (₹ Crore) - own company inputs used by the analysis
A7: Line Item | C7: Kansai Nerolac
C8: FY2024-25 | D8: FY2025-26
A9: Inventories (closing stock) | C9: 1609.71 | D9: 1492.92
A10: Trade Receivables (current) | C10: 1274.7 | D10: 1379.83
A11: Cash & Cash Equivalents | C11: 85.72 | D11: 184.12
A12: Bank Balances other than Cash & Cash Equivalents | C12: 174.52 | D12: 7.97
A13: Other Current Assets (investments, loans, other financial & non-financial assets) | C13: 2029.11 | D13: 2549.88
A14: Total Current Assets | C14: 5173.76 | D14: 5614.72
A15: Trade Payables | C15: 1023.65 | D15: 1075.42
A16: Short-term Borrowings | C16: 0 | D16: 0
A17: Other Current Liabilities & Provisions (incl. current lease liabilities) | C17: 263.68 | D17: 422.77
A18: Total Current Liabilities | C18: 1287.33 | D18: 1498.19
A19: Total Borrowings (interest-bearing debt; excludes lease liabilities) | C19: 0 | D19: 0
A20: Total Equity / Shareholders’ Funds | C20: 6366.23 | D20: 6695.77
... A29: Total Lease Liabilities, Ind AS 116 - excluded from Total Borrowings above (memo) | C29: 171.2 | D29: 217.2
A31: Opening Balances - FY2023–24 Closing (Reference Only)
A32: These three FY2023-24 closing figures come from the comparative column already printed in each company’s FY2024-25 annual report (see citations below) and are used only to compute average-balance ratios for FY2024-25 in the tables below - they are not part of the two-year dataset used in the rest of this analysis.
A34: Line Item - As at 31 March 2024 | C34: Kansai Nerolac
A35: Inventories (closing stock) | C35: 1616.04
A36: Total Equity / Shareholders’ Funds | C36: 5653.12
A37: Total Assets | C37: 7224.8
A39: Ratio Analysis - Formula, Company Figures & Industry Average
A40: Methodology: Debt-to-Equity excludes Ind AS 116 lease liabilities; a separate lease-inclusive ratio adds Total Lease Liabilities. The Industry Average is the simple arithmetic mean of the same ratio for the five selected companies, including the company being analysed. Supporting financial data is maintained in the Industry Summary sheet, while company-specific ratios are calculated separately for FY2024–25 and FY2025–26. Ratios based on average balances use FY2023–24 closing balances and FY2024–25 closing balances for FY2024–25, and FY2024–25 and FY2025–26 closing balances for FY2025–26. Materials-Consumption Turnover is used as a proxy for Inventory Turnover because a single consolidated Cost of Goods Sold figure is not available for all companies.
A42: B. Liquidity
C43: FY2024-25 | E43: FY2025-26
A44: Ratio | B44: Formula | C44: Company | D44: Industry Avg | E44: Company | F44: Industry Avg
A45: Current Ratio | B45: Current Assets ÷ Current Liabilities | C45: =C14/C18 -> 4.018985 | D45: ='Industry Summary'!L48 -> 2.4353778 | E45: =D14/D18 -> 3.7476689 | F45: ='Industry Summary'!L60 -> 2.4275972
A46: Quick Ratio | B46: (Current Assets − Inventories) ÷ Current Liabilities | C46: =(C14-C9)/C18 -> 2.7685597 | D46: ='Industry Summary'!L49 -> 1.5808142 | E46: =(D14-D9)/D18 -> 2.7511864 | F46: ='Industry Summary'!L61 -> 1.6811362
A47: Cash Ratio | B47: (Cash & Cash Equivalents + Other Bank Balances) ÷ Current Liabilities | C47: =(C11+C12)/C18 -> 0.20215485 | D47: ='Industry Summary'!L50 -> 0.15262564 | E47: =(D11+D12)/D18 -> 0.12821471 | F47: ='Industry Summary'!L62 -> 0.11967229
A49: C. Solvency and Leverage
C50: FY2024-25 | E50: FY2025-26
A51: Ratio | B51: Formula | C51: Company | D51: Industry Avg | E51: Company | F51: Industry Avg
A52: Debt-to-Equity | B52: Total Borrowings ÷ Total Equity | C52: =C19/C20 -> 0 | D52: ='Industry Summary'!L54 -> 0.00042882759 | E52: =D19/D20 -> 0 | F52: ='Industry Summary'!L66 -> 0.011449285
A53: Debt-to-Equity (incl. Lease Liabilities) | B53: (Total Borrowings + Total Lease Liabilities) ÷ Total Equity | C53: =(C19+C29)/C20 -> 0.026891897 | D53: ='Industry Summary'!L55 -> 0.048453003 | E53: =(D19+D29)/D20 -> 0.03243839 | F53: ='Industry Summary'!L67 -> 0.053467726
A55: D. Profitability
C56: FY2024-25 | E56: FY2025-26
...

Sheet Asian Paints
A1: Asian Paints Ltd. - Financial Analysis
A2: Standalone Financial Statements | FY2024–25 & FY2025–26 (FY2023–24 Opening Balances) | Amounts in ₹ Crore Unless Stated | Industry Average: Simple Mean of Five Companies
A4: Financial Statement Analysis
A6: A. Key Financial Figures - Financial Statement Data (₹ Crore) - own company inputs used by the analysis
A7: Line Item | C7: Asian Paints
C8: FY2024-25 | D8: FY2025-26
A9: Inventories (closing stock) | C9: 5848.23 | D9: 4824.74
A10: Trade Receivables (current) | C10: 3197.55 | D10: 3227.71
A11: Cash & Cash Equivalents | C11: 176.19 | D11: 395.38
A12: Bank Balances other than Cash & Cash Equivalents | C12: 26.09 | D12: 50.96
A13: Other Current Assets (investments, loans, other financial & non-financial assets) | C13: 5039.88 | D13: 8757.44
A14: Total Current Assets | C14: 14287.94 | D14: 17256.23
A15: Trade Payables | C15: 3123.69 | D15: 3114.48
A16: Short-term Borrowings | C16: 2.15 | D16: 340.73
A17: Other Current Liabilities & Provisions (incl. current lease liabilities) | C17: 3090.36 | D17: 3550.67
A18: Total Current Liabilities | C18: 6216.2 | D18: 7005.88
A19: Total Borrowings (interest-bearing debt; excludes lease liabilities) | C19: 39.4 | D19: 1189.67
A20: Total Equity / Shareholders’ Funds | C20: 18983.48 | D20: 20781.56
... A29: Total Lease Liabilities, Ind AS 116 - excluded from Total Borrowings above (memo) | C29: 1159.42 | D29: 1179.29
A31: Opening Balances - FY2023–24 Closing (Reference Only)
A32: These three FY2023-24 closing figures come from the comparative column already printed in each company’s FY2024-25 annual report (see citations below) and are used only to compute average-balance ratios for FY2024-25 in the tables below - they are not part of the two-year dataset used in the rest of this analysis.
A34: Line Item - As at 31 March 2024 | C34: Asian Paints
A35: Inventories (closing stock) | C35: 5155.59
A36: Total Equity / Shareholders’ Funds | C36: 18288.66
A37: Total Assets | C37: 26035.64
A39: Ratio Analysis - Formula, Company Figures & Industry Average
A40: Methodology: Debt-to-Equity excludes Ind AS 116 lease liabilities; a separate lease-inclusive ratio adds Total Lease Liabilities. The Industry Average is the simple arithmetic mean of the same ratio for the five selected companies, including the company being analysed. Supporting financial data is maintained in the Industry Summary sheet, while company-specific ratios are calculated separately for FY2024–25 and FY2025–26. Ratios based on average balances use FY2023–24 closing balances and FY2024–25 closing balances for FY2024–25, and FY2024–25 and FY2025–26 closing balances for FY2025–26. Materials-Consumption Turnover is used as a proxy for Inventory Turnover because a single consolidated Cost of Goods Sold figure is not available for all companies.
A42: B. Liquidity
C43: FY2024-25 | E43: FY2025-26
A44: Ratio | B44: Formula | C44: Company | D44: Industry Avg | E44: Company | F44: Industry Avg
A45: Current Ratio | B45: Current Assets ÷ Current Liabilities | C45: =C14/C18 -> 2.2985007 | D45: ='Industry Summary'!L48 -> 2.4353778 | E45: =D14/D18 -> 2.4631067 | F45: ='Industry Summary'!L60 -> 2.4275972
A46: Quick Ratio | B46: (Current Assets − Inventories) ÷ Current Liabilities | C46: =(C14-C9)/C18 -> 1.357696 | D46: ='Industry Summary'!L49 -> 1.5808142 | E46: =(D14-D9)/D18 -> 1.7744366 | F46: ='Industry Summary'!L61 -> 1.6811362
A47: Cash Ratio | B47: (Cash & Cash Equivalents + Other Bank Balances) ÷ Current Liabilities | C47: =(C11+C12)/C18 -> 0.032540781 | D47: ='Industry Summary'!L50 -> 0.15262564 | E47: =(D11+D12)/D18 -> 0.063709341 | F47: ='Industry Summary'!L62 -> 0.11967229
A49: C. Solvency and Leverage
C50: FY2024-25 | E50: FY2025-26
A51: Ratio | B51: Formula | C51: Company | D51: Industry Avg | E51: Company | F51: Industry Avg
A52: Debt-to-Equity | B52: Total Borrowings ÷ Total Equity | C52: =C19/C20 -> 0.0020754888 | D52: ='Industry Summary'!L54 -> 0.00042882759 | E52: =D19/D20 -> 0.057246424 | F52: ='Industry Summary'!L66 -> 0.011449285
A53: Debt-to-Equity (incl. Lease Liabilities) | B53: (Total Borrowings + Total Lease Liabilities) ÷ Total Equity | C53: =(C19+C29)/C20 -> 0.063150697 | D53: ='Industry Summary'!L55 -> 0.048453003 | E53: =(D19+D29)/D20 -> 0.11399337 | F53: ='Industry Summary'!L67 -> 0.053467726
A55: D. Profitability
C56: FY2024-25 | E56: FY2025-26
...

Sheet JSW Dulux
A1: JSW Dulux Ltd. (formerly Akzo Nobel India Ltd.) - Financial Analysis
A2: Standalone Financial Statements | FY2024–25 & FY2025–26 (FY2023–24 Opening Balances) | Amounts in ₹ Crore Unless Stated | Industry Average: Simple Mean of Five Companies
A4: Financial Statement Analysis
A6: A. Key Financial Figures - Financial Statement Data (₹ Crore) - own company inputs used by the analysis
A7: Line Item | C7: JSW Dulux
C8: FY2024-25 | D8: FY2025-26
A9: Inventories (closing stock) | C9: 604.7 | D9: 571.1
A10: Trade Receivables (current) | C10: 584.9 | D10: 602.9
A11: Cash & Cash Equivalents | C11: 247.2 | D11: 203.1
A12: Bank Balances other than Cash & Cash Equivalents | C12: 52.3 | D12: 53.9
A13: Other Current Assets (investments, loans, other financial & non-financial assets) | C13: 511.3 | D13: 289.4
A14: Total Current Assets | C14: 2000.4 | D14: 1720.4
A15: Trade Payables | C15: 956.6 | D15: 753.6
A16: Short-term Borrowings | C16: 0 | D16: 0
A17: Other Current Liabilities & Provisions (incl. current lease liabilities) | C17: 493.6 | D17: 380.7
A18: Total Current Liabilities | C18: 1450.2 | D18: 1134.3
A19: Total Borrowings (interest-bearing debt; excludes lease liabilities) | C19: 0 | D19: 0
A20: Total Equity / Shareholders’ Funds | C20: 1328.7 | D20: 2394.2
... A29: Total Lease Liabilities, Ind AS 116 - excluded from Total Borrowings above (memo) | C29: 62.1 | D29: 79.1
A31: Opening Balances - FY2023–24 Closing (Reference Only)
A32: These three FY2023-24 closing figures come from the comparative column already printed in each company’s FY2024-25 annual report (see citations below) and are used only to compute average-balance ratios for FY2024-25 in the tables below - they are not part of the two-year dataset used in the rest of this analysis.
A34: Line Item - As at 31 March 2024 | C34: JSW Dulux
A35: Inventories (closing stock) | C35: 611.5
A36: Total Equity / Shareholders’ Funds | C36: 1329.2
A37: Total Assets | C37: 2903
A39: Ratio Analysis - Formula, Company Figures & Industry Average
A40: Methodology: Debt-to-Equity excludes Ind AS 116 lease liabilities; a separate lease-inclusive ratio adds Total Lease Liabilities. The Industry Average is the simple arithmetic mean of the same ratio for the five selected companies, including the company being analysed. Supporting financial data is maintained in the Industry Summary sheet, while company-specific ratios are calculated separately for FY2024–25 and FY2025–26. Ratios based on average balances use FY2023–24 closing balances and FY2024–25 closing balances for FY2024–25, and FY2024–25 and FY2025–26 closing balances for FY2025–26. Materials-Consumption Turnover is used as a proxy for Inventory Turnover because a single consolidated Cost of Goods Sold figure is not available for all companies.
A42: B. Liquidity
C43: FY2024-25 | E43: FY2025-26
A44: Ratio | B44: Formula | C44: Company | D44: Industry Avg | E44: Company | F44: Industry Avg
A45: Current Ratio | B45: Current Assets ÷ Current Liabilities | C45: =C14/C18 -> 1.3793959 | D45: ='Industry Summary'!L48 -> 2.4353778 | E45: =D14/D18 -> 1.5167063 | F45: ='Industry Summary'!L60 -> 2.4275972
A46: Quick Ratio | B46: (Current Assets − Inventories) ÷ Current Liabilities | C46: =(C14-C9)/C18 -> 0.96241898 | D46: ='Industry Summary'!L49 -> 1.5808142 | E46: =(D14-D9)/D18 -> 1.013224 | F46: ='Industry Summary'!L61 -> 1.6811362
A47: Cash Ratio | B47: (Cash & Cash Equivalents + Other Bank Balances) ÷ Current Liabilities | C47: =(C11+C12)/C18 -> 0.20652324 | D47: ='Industry Summary'!L50 -> 0.15262564 | E47: =(D11+D12)/D18 -> 0.22657145 | F47: ='Industry Summary'!L62 -> 0.11967229
A49: C. Solvency and Leverage
C50: FY2024-25 | E50: FY2025-26
A51: Ratio | B51: Formula | C51: Company | D51: Industry Avg | E51: Company | F51: Industry Avg
A52: Debt-to-Equity | B52: Total Borrowings ÷ Total Equity | C52: =C19/C20 -> 0 | D52: ='Industry Summary'!L54 -> 0.00042882759 | E52: =D19/D20 -> 0 | F52: ='Industry Summary'!L66 -> 0.011449285
A53: Debt-to-Equity (incl. Lease Liabilities) | B53: (Total Borrowings + Total Lease Liabilities) ÷ Total Equity | C53: =(C19+C29)/C20 -> 0.046737413 | D53: ='Industry Summary'!L55 -> 0.048453003 | E53: =(D19+D29)/D20 -> 0.033038176 | F53: ='Industry Summary'!L67 -> 0.053467726
A55: D. Profitability
C56: FY2024-25 | E56: FY2025-26
...

Sheet Indigo Paints
A1: Indigo Paints Ltd. - Financial Analysis
A2: Standalone Financial Statements | FY2024–25 & FY2025–26 (FY2023–24 Opening Balances) | Amounts in ₹ Crore Unless Stated | Industry Average: Simple Mean of Five Companies
A4: Financial Statement Analysis
A6: A. Key Financial Figures - Financial Statement Data (₹ Crore) - own company inputs used by the analysis
A7: Line Item | C7: Indigo Paints
C8: FY2024-25 | D8: FY2025-26
A9: Inventories (closing stock) | C9: 149.13 | D9: 173.07
A10: Trade Receivables (current) | C10: 219.92 | D10: 257.29
A11: Cash & Cash Equivalents | C11: 37.09 | D11: 28.54
A12: Bank Balances other than Cash & Cash Equivalents | C12: 0.01 | D12: 0.01
A13: Other Current Assets (investments, loans, other financial & non-financial assets) | C13: 240.14 | D13: 304.26
A14: Total Current Assets | C14: 646.29 | D14: 763.17
A15: Trade Payables | C15: 165.29 | D15: 199.44
A16: Short-term Borrowings | C16: 0 | D16: 0
A17: Other Current Liabilities & Provisions (incl. current lease liabilities) | C17: 104.19 | D17: 143.48
A18: Total Current Liabilities | C18: 269.48 | D18: 342.92
A19: Total Borrowings (interest-bearing debt; excludes lease liabilities) | C19: 0 | D19: 0
A20: Total Equity / Shareholders’ Funds | C20: 1048.14 | D20: 1182.35
... A29: Total Lease Liabilities, Ind AS 116 - excluded from Total Borrowings above (memo) | C29: 19.7 | D29: 18.38
A31: Opening Balances - FY2023–24 Closing (Reference Only)
A32: These three FY2023-24 closing figures come from the comparative column already printed in each company’s FY2024-25 annual report (see citations below) and are used only to compute average-balance ratios for FY2024-25 in the tables below - they are not part of the two-year dataset used in the rest of this analysis.
A34: Line Item - As at 31 March 2024 | C34: Indigo Paints
A35: Inventories (closing stock) | C35: 166.2
A36: Total Equity / Shareholders’ Funds | C36: 915.07
A37: Total Assets | C37: 1221.95
A39: Ratio Analysis - Formula, Company Figures & Industry Average
A40: Methodology: Debt-to-Equity excludes Ind AS 116 lease liabilities; a separate lease-inclusive ratio adds Total Lease Liabilities. The Industry Average is the simple arithmetic mean of the same ratio for the five selected companies, including the company being analysed. Supporting financial data is maintained in the Industry Summary sheet, while company-specific ratios are calculated separately for FY2024–25 and FY2025–26. Ratios based on average balances use FY2023–24 closing balances and FY2024–25 closing balances for FY2024–25, and FY2024–25 and FY2025–26 closing balances for FY2025–26. Materials-Consumption Turnover is used as a proxy for Inventory Turnover because a single consolidated Cost of Goods Sold figure is not available for all companies.
A42: B. Liquidity
C43: FY2024-25 | E43: FY2025-26
A44: Ratio | B44: Formula | C44: Company | D44: Industry Avg | E44: Company | F44: Industry Avg
A45: Current Ratio | B45: Current Assets ÷ Current Liabilities | C45: =C14/C18 -> 2.3982856 | D45: ='Industry Summary'!L48 -> 2.4353778 | E45: =D14/D18 -> 2.2255045 | F45: ='Industry Summary'!L60 -> 2.4275972
A46: Quick Ratio | B46: (Current Assets − Inventories) ÷ Current Liabilities | C46: =(C14-C9)/C18 -> 1.8448864 | D46: ='Industry Summary'!L49 -> 1.5808142 | E46: =(D14-D9)/D18 -> 1.7208095 | F46: ='Industry Summary'!L61 -> 1.6811362
A47: Cash Ratio | B47: (Cash & Cash Equivalents + Other Bank Balances) ÷ Current Liabilities | C47: =(C11+C12)/C18 -> 0.13767255 | D47: ='Industry Summary'!L50 -> 0.15262564 | E47: =(D11+D12)/D18 -> 0.08325557 | F47: ='Industry Summary'!L62 -> 0.11967229
A49: C. Solvency and Leverage
C50: FY2024-25 | E50: FY2025-26
A51: Ratio | B51: Formula | C51: Company | D51: Industry Avg | E51: Company | F51: Industry Avg
A52: Debt-to-Equity | B52: Total Borrowings ÷ Total Equity | C52: =C19/C20 -> 0 | D52: ='Industry Summary'!L54 -> 0.00042882759 | E52: =D19/D20 -> 0 | F52: ='Industry Summary'!L66 -> 0.011449285
A53: Debt-to-Equity (incl. Lease Liabilities) | B53: (Total Borrowings + Total Lease Liabilities) ÷ Total Equity | C53: =(C19+C29)/C20 -> 0.018795199 | D53: ='Industry Summary'!L55 -> 0.048453003 | E53: =(D19+D29)/D20 -> 0.015545312 | F53: ='Industry Summary'!L67 -> 0.053467726
A55: D. Profitability
C56: FY2024-25 | E56: FY2025-26
...

Sheet Industry Summary
A1: Paints & Coatings Industry - Combined Industry Summary
A2: Berger Paints | Kansai Nerolac | Asian Paints | Indigo Paints | JSW Dulux (formerly Akzo Nobel India) - FY2021-22 to FY2025-26
A3: Ratios, DuPont components and Industry Averages on this sheet are live Excel formulas calculated on this sheet from the “Five-Company Financial Data - Local Calculation Support” tables in section 1 at the top of the sheet; no formula refers to any company worksheet, so this sheet calculates independently. Company-profile, market-capitalisation, share-price and Leaders & Laggards items are static copies of the verified values on each company sheet (see each company sheet's Sources & page citations for the primary-source evidence). Unavailable or non-comparable figures are labelled "n/a" or "not separately verified" rather than estimated.
A6: 1. Five-Company Financial Data - Local Calculation Support
A7: Self-contained sheet: the five tables below (side by side) hold the validated standalone book values (₹ Crore) for FY2024-25 and FY2025-26 plus FY2023-24 opening / base figures. Blue = input. Every ratio, DuPont component and Industry Average on this sheet is a live formula calculated from these tables; no formula refers to any company worksheet. Scroll right for all five tables (column A stays in view).
A9: Five-company book values (₹ Crore, Standalone) - Berger Paints | Asian Paints | Indigo Paints | JSW Dulux | Kansai Nerolac - one table per company, side by side
A10: Line item (₹ Crore) | B10: Berger Paints India Ltd. | F10: Asian Paints Ltd. | J10: Indigo Paints Ltd. | N10: JSW Dulux Ltd. (formerly Akzo Nobel India Ltd.) | R10: Kansai Nerolac Paints Ltd.
B11: FY2024-25 | D11: FY2025-26 | F11: FY2024-25 | H11: FY2025-26 | J11: FY2024-25 | L11: FY2025-26 | N11: FY2024-25 | P11: FY2025-26 | R11: FY2024-25 | T11: FY2025-26
A12: Reporting basis (full notes in section J) | B12: ₹ Crore as reported (standalone) | F12: ₹ Crore; FY2024-25 as originally published (restated in FY2025-26 report) | J12: Reported in ₹ lakh; converted to ₹ Crore (÷100) | N12: Reported in ₹ million; converted to ₹ Crore (÷10); FY2024-25 revenue regrouped | R12: ₹ Crore as reported; exceptional items in both years
A13: Inventories (closing stock) | B13: 2206.6 | D13: 2225.6 | F13: 5848.23 | H13: 4824.74 | J13: 149.13 | L13: 173.07 | N13: 604.7 | P13: 571.1 | R13: 1609.71 | T13: 1492.92
A14: Trade Receivables (current) | B14: 1124.37 | D14: 1129.27 | F14: 3197.55 | H14: 3227.71 | J14: 219.92 | L14: 257.29 | N14: 584.9 | P14: 602.9 | R14: 1274.7 | T14: 1379.83
A15: Cash & Cash Equivalents | B15: 141.39 | D15: 151.94 | F15: 176.19 | H15: 395.38 | J15: 37.09 | L15: 28.54 | N15: 247.2 | P15: 203.1 | R15: 85.72 | T15: 184.12
A16: Bank Balances other than Cash & Cash Equivalents | B16: 224.46 | D16: 55.01 | F16: 26.09 | H16: 50.96 | J16: 0.01 | L16: 0.01 | N16: 52.3 | P16: 53.9 | R16: 174.52 | T16: 7.97
A17: Other Current Assets (investments, loans, other) | B17: 436.98 | D17: 1118.69 | F17: 5039.88 | H17: 8757.44 | J17: 240.14 | L17: 304.26 | N17: 511.3 | P17: 289.4 | R17: 2029.11 | T17: 2549.88
A18: Total Current Assets | B18: 4133.8 | D18: 4680.51 | F18: 14287.94 | H18: 17256.23 | J18: 646.29 | L18: 763.17 | N18: 2000.4 | P18: 1720.4 | R18: 5173.76 | T18: 5614.72
A19: Trade Payables | B19: 1569.34 | D19: 1522.26 | F19: 3123.69 | H19: 3114.48 | J19: 165.29 | L19: 199.44 | N19: 956.6 | P19: 753.6 | R19: 1023.65 | T19: 1075.42
A20: Short-term Borrowings | B20: 0.39 | D20: 0 | F20: 2.15 | H20: 340.73 | J20: 0 | L20: 0 | N20: 0 | P20: 0 | R20: 0 | T20: 0
A21: Other Current Liabilities & Provisions | B21: 416.03 | D21: 619.85 | F21: 3090.36 | H21: 3550.67 | J21: 104.19 | L21: 143.48 | N21: 493.6 | P21: 380.7 | R21: 263.68 | T21: 422.77
A22: Total Current Liabilities | B22: 1985.76 | D22: 2142.11 | F22: 6216.2 | H22: 7005.88 | J22: 269.48 | L22: 342.92 | N22: 1450.2 | P22: 1134.3 | R22: 1287.33 | T22: 1498.19
A23: Total Borrowings (excl. lease liabilities) | B23: 0.39 | D23: 0 | F23: 39.4 | H23: 1189.67 | J23: 0 | L23: 0 | N23: 0 | P23: 0 | R23: 0 | T23: 0
A24: Total Equity / Shareholders’ Funds | B24: 5681.06 | D24: 6342.9 | F24: 18983.48 | H24: 20781.56 | J24: 1048.14 | L24: 1182.35 | N24: 1328.7 | P24: 2394.2 | R24: 6366.23 | T24: 6695.77
... A35: Finance Costs (Standalone) | B35: 47.86 | D35: 45.6 | F35: 143.77 | H35: 127.35 | J35: 2.96 | L35: 2.39 | N35: 9.8 | P35: 12.1 | R35: 15.09 | T35: 18.41
A36: Opening balances - FY2023-24 closing (as at 31 March 2024) | B36: FY2023-24 | F36: FY2023-24 | J36: FY2023-24 | N36: FY2023-24 | R36: FY2023-24
A37: Inventories (closing stock) | B37: 2019.43 | F37: 5155.59 | J37: 166.2 | N37: 611.5 | R37: 1616.04
A38: Total Equity / Shareholders’ Funds | B38: 5005.24 | F38: 18288.66 | J38: 915.07 | N38: 1329.2 | R38: 5653.12
A39: Total Assets | B39: 7581.66 | F39: 26035.64 | J39: 1221.95 | N39: 2903 | R39: 7224.8
A40: Revenue from Operations (growth base year) | B40: 10002.93 | F40: 31226.98 | J40: 1254.86 | N40: 3961.6 | R40: 7393.3
A42: Reporting-basis notes: Asian Paints - FY2024-25 figures as originally published (the FY2025-26 report restates comparatives for an amalgamation, differences about 0.1% or less); Revenue, Trade Payables and Total Expenses are sums of reported lines. Indigo Paints - converted from ₹ lakh (÷100); Cost of Materials Consumed is the P&L line “Cost of raw materials and components consumed”. JSW Dulux - converted from ₹ million (÷10); FY2024-25 Revenue ₹4,091.2 Cr and Total Expenses ₹3,549.1 Cr as originally published (FY2025-26 report regrouped promotional spends: ₹4,069.3 Cr / ₹3,527.2 Cr; profit unchanged); FY2025-26 profit before tax includes a ₹1,846.3 Cr net exceptional gain (mainly the profit on the slump sale of two divisions). Berger Paints and Kansai Nerolac - as reported. Trade Payables for Berger, Indigo, JSW and Asian Paints are the sum of the MSME and other-creditor lines. See each company's own worksheet for full source citations.
A43: 2. Financial Ratios - Company Figures, FY2024-25 & FY2025-26
A44: Formula definitions and average-balance methodology are documented on each company's own “Ratio Analysis” table. Columns B–F show each company's own (“Company”) figures; column G, “Industry Avg (5 companies)”, is the simple arithmetic mean of those five company figures for the same year (a live formula); the company figures themselves are calculated on this sheet from the local book-value tables in section 1 at the top of the sheet - a benchmark of the five companies selected for this project, not an official industry-wide average.
A46: FY2024-25
B47: Berger Paints | D47: Asian Paints | F47: Indigo Paints | H47: JSW Dulux (fmrly Akzo Nobel India) | J47: Kansai Nerolac | L47: Industry Avg (5 companies)
A48: Current Ratio | B48: =B18/B22 -> 2.0817219 | D48: =F18/F22 -> 2.2985007 | F48: =J18/J22 -> 2.3982856 | H48: =N18/N22 -> 1.3793959 | J48: =R18/R22 -> 4.018985 | L48: =AVERAGE(B48:J48) -> 2.4353778
A49: Quick Ratio | B49: =(B18-B13)/B22 -> 0.97051003 | D49: =(F18-F13)/F22 -> 1.357696 | F49: =(J18-J13)/J22 -> 1.8448864 | H49: =(N18-N13)/N22 -> 0.96241898 | J49: =(R18-R13)/R22 -> 2.7685597 | L49: =AVERAGE(B49:J49) -> 1.5808142
A50: Cash Ratio | B50: =(B15+B16)/B22 -> 0.18423677 | D50: =(F15+F16)/F22 -> 0.032540781 | F50: =(J15+J16)/J22 -> 0.13767255 | H50: =(N15+N16)/N22 -> 0.20652324 | J50: =(R15+R16)/R22 -> 0.20215485 | L50: =AVERAGE(B50:J50) -> 0.15262564
A51: Net Profit Margin | B51: =B30/B26 -> 0.105957 | D51: =F30/F26 -> 0.12130486 | F51: =J30/J26 -> 0.11270054 | H51: =N30/N26 -> 0.10476144 | J51: =R30/R26 -> 0.13622509 | L51: =AVERAGE(B51:J51) -> 0.11618978
A52: Return on Assets (ROA) - avg. basis | B52: =B30/AVERAGE(B39,B25) -> 0.13675446 | D52: =F30/AVERAGE(F39,F25) -> 0.13607763 | F52: =J30/AVERAGE(J39,J25) -> 0.11159351 | H52: =N30/AVERAGE(N39,N25) -> 0.14767598 | J52: =R30/AVERAGE(R39,R25) -> 0.13442639 | L52: =AVERAGE(B52:J52) -> 0.13330559
A53: Return on Equity (ROE) - avg. basis | B53: =B30/AVERAGE(B38,B24) -> 0.20166007 | D53: =F30/AVERAGE(F38,F24) -> 0.19236245 | F53: =J30/AVERAGE(J38,J24) -> 0.14663739 | H53: =N30/AVERAGE(N38,N24) -> 0.32251025 | J53: =R30/AVERAGE(R38,R24) -> 0.16993265 | L53: =AVERAGE(B53:J53) -> 0.20662056
A54: Debt-to-Equity | B54: =B23/B24 -> 6.8649161e-05 | D54: =F23/F24 -> 0.0020754888 | F54: =J23/J24 -> 0 | H54: =N23/N24 -> 0 | J54: =R23/R24 -> 0 | L54: =AVERAGE(B54:J54) -> 0.00042882759
A55: Debt-to-Equity (incl. Lease Liab.) | B55: =(B23+B33)/B24 -> 0.086689808 | D55: =(F23+F33)/F24 -> 0.063150697 | F55: =(J23+J33)/J24 -> 0.018795199 | H55: =(N23+N33)/N24 -> 0.046737413 | J55: =(R23+R33)/R24 -> 0.026891897 | L55: =AVERAGE(B55:J55) -> 0.048453003
...
